Workbook
Name ZZZ: Parc!$CTC$105
Name ZZZ105: Parc!$CTC$105

Sheet Parc
A1: Endpoint Name | B1: Last Logged In User | C1: ACTIONS | D1: Date d'exdecution | E1: Device Type | F1: spécifications | G1: Model Name | H1: CPU Type | I1: Disk Encryption | J1: Console Visible IP | K1: Agent Version | L1: Serial Number | M1: Subscribed On | N1: OS Version | O1: Architecture | P1: Memory | Q1: upgrade Ram | R1: SUpp user | S1: Bâtiment | T1: CPU Count | U1: Core Count | V1: Management Connectivity | W1: Network Status | X1: Update Status | Y1: Scan Status | Z1: Last Reported IP | AA1: Pending Uninstall | AB1: Agent UUID | AC1: Agent ID | AD1: Customer Identifier | AE1: Console Migration Status | AF1: Operational State | AG1: Operational State Expiration | AH1: Last Reboot Date | AI1: Installer Type | AJ1: Reboot Required due to Threat | AK1: User Action Required | AL1: Remote Profiling State | AM1: Remote Profiling Expiration | AN1: Storage Type | AO1: Storage Name | AP1: Cloud Account | AQ1: Cloud Location | AR1: Cloud Network | AS1: Cloud Image | AT1: Cloud Tags | AU1: Cloud Instance Size | AV1: Cloud Instance ID | AW1: Cloud Security Group | AX1: Cluster Name | AY1: K8s Type | AZ1: K8s Version | BA1: Agent Namespace | BB1: Agent Pod Name | BC1: K8s Node Name | BD1: K8s Node Labels | BE1: ECS Type | BF1: ECS Version | BG1: ECS Cluster Name | BH1: ECS Task Arn | BI1: ECS Task Availability Zone | BJ1: ECS Service Name | BK1: ECS Service Arn | BL1: ECS Task Definition Family | BM1: ECS Task Definition Revision | BN1: ECS Task Definition Arn | BO1: Is Uninstalled | BP1: Decommissioned at | BQ1: Missing Permissions | BR1: Service | BS1: Réaffecté
A2: AMP-12-007D | B2: gberva | C2: A CHANGER | D2: changé 24/10/2025 | E2: desktop | G2: Dell Inc. - OptiPlex 9010 | H2: Intel(R) Core(TM) i5-3550 CPU @ 3.30GHz | I2: Off | J2: 185.149.219.108 | K2: 23.4.4.223 | L2: DPV9D5J | M2: May 31, 2023 06:22:10 PM | N2: Windows 10 Professionnel,19045 | O2: 64 bit | P2: 8 GB | S2: historique | T2: 1 | U2: 4 | V2: Offline | W2: Connected | X2: Up to date | Y2: N/A | Z2: 192.168.16.66 | AA2: No | AB2: eba56c7003e9464990aa3f46a6594827 | AC2: 1.69725e+18 | AD2: N/A | AE2: N/A | AF2: Not disabled | AG2: N/A | AH2: May 27, 2025 06:41:05 AM | AI2: MSI | AJ2: No | AK2: No | AL2: disabled | AM2: N/A | AN2: N/A | AO2: N/A | AP2: N/A | AQ2: N/A | AR2: N/A | AS2: N/A | AT2: N/A | AU2: N/A | AV2: N/A | AW2: N/A | AX2: N/A | AY2: N/A | AZ2: N/A | BA2: N/A | BB2: N/A | BC2: N/A | BD2: N/A | BE2: N/A | BF2: N/A | BG2: N/A | BH2: N/A | BI2: N/A | BJ2: N/A | BK2: N/A | BL2: N/A | BM2: N/A | BN2: N/A | BO2: No | BP2: N/A | BQ2: N/A | BR2: image
A3: AMP-12-022L | B3: pgeneau | C3: UPDATE | D3: maj 04/11/2025 | E3: laptop | G3: Dell Inc. - Latitude E5530 non-vPro | H3: Intel(R) Core(TM) i5-3210M CPU @ 2.50GHz | I3: Off | J3: 82.96.154.199 | K3: 23.4.4.223 | L3: 74VZFV1 | M3: May 02, 2024 01:30:44 PM | N3: Windows 10 Professionnel,19045 | O3: 64 bit | P3: 4 GB | T3: 1 | U3: 2 | V3: Online | W3: Connected | X3: Up to date | Y3: N/A | Z3: 172.20.16.29 | AA3: No | AB3: fdf414dd9d374882aa4c8b6975566e85 | AC3: 1.94136e+18 | AD3: N/A | AE3: N/A | AF3: Not disabled | AG3: N/A | AH3: May 21, 2025 06:22:13 AM | AI3: MSI | AJ3: No | AK3: No | AL3: disabled | AM3: N/A | AN3: N/A | AO3: N/A | AP3: N/A | AQ3: N/A | AR3: N/A | AS3: N/A | AT3: N/A | AU3: N/A | AV3: N/A | AW3: N/A | AX3: N/A | AY3: N/A | AZ3: N/A | BA3: N/A | BB3: N/A | BC3: N/A | BD3: N/A | BE3: N/A | BF3: N/A | BG3: N/A | BH3: N/A | BI3: N/A | BJ3: N/A | BK3: N/A | BL3: N/A | BM3: N/A | BN3: N/A | BO3: No | BP3: N/A | BQ3: N/A
A4: AMP-13-001D | B4: magups | C4: UPDATE | D4: MAJ 26/11/2025 | E4: desktop | F4: Venir de 12H30 à 13H30 | G4: Dell Inc. - OptiPlex 3020 | H4: Intel(R) Core(TM) i3-4130 CPU @ 3.40GHz | I4: Off | J4: 185.149.219.108 | K4: 23.4.4.223 | L4: 1YTQPZ1 | M4: Jun 07, 2023 03:04:20 PM | N4: Windows 10 Professionnel,19045 | O4: 64 bit | P4: 4 GB | Q4: 4>8 | S4: Logistique | T4: 1 | U4: 2 | V4: Online | W4: Connected | X4: Up to date | Y4: N/A | Z4: 192.168.16.137 | AA4: No | AB4: dfe61ac38445401d87ff8822e738a40c | AC4: 1.70223e+18 | AD4: N/A | AE4: N/A | AF4: Not disabled | AG4: N/A | AH4: May 20, 2025 12:21:53 PM | AI4: MSI | AJ4: No | AK4: No | AL4: disabled | AM4: N/A | AN4: N/A | AO4: N/A | AP4: N/A | AQ4: N/A | AR4: N/A | AS4: N/A | AT4: N/A | AU4: N/A | AV4: N/A | AW4: N/A | AX4: N/A | AY4: N/A | AZ4: N/A | BA4: N/A | BB4: N/A | BC4: N/A | BD4: N/A | BE4: N/A | BF4: N/A | BG4: N/A | BH4: N/A | BI4: N/A | BJ4: N/A | BK4: N/A | BL4: N/A | BM4: N/A | BN4: N/A | BO4: No | BP4: N/A | BQ4: N/A | BR4: Magasin
A5: AMP-13-002D | B5: icontrole | C5: UPDATE | D5: maj 22/10/2025 | E5: desktop | G5: Dell Inc. - OptiPlex 3010 | H5: Intel(R) Core(TM) i3-3220 CPU @ 3.30GHz | I5: Off | J5: 185.149.219.108 | K5: 23.4.4.223 | L5: 54F3J5J | M5: Jun 07, 2023 03:05:11 PM | N5: Windows 10 Professionnel,19045 | O5: 64 bit | P5: 4 GB | Q5: 4>8 | S5: historique | T5: 1 | U5: 2 | V5: Offline | W5: Connected | X5: Up to date | Y5: N/A | Z5: 192.168.17.160 | AA5: No | AB5: e834e98bcbfd494b918ae3399ea5d051 | AC5: 1.70223e+18 | AD5: N/A | AE5: N/A | AF5: Not disabled | AG5: N/A | AH5: May 19, 2025 01:06:09 PM | AI5: MSI | AJ5: No | AK5: No | AL5: disabled | AM5: N/A | AN5: N/A | AO5: N/A | AP5: N/A | AQ5: N/A | AR5: N/A | AS5: N/A | AT5: N/A | AU5: N/A | AV5: N/A | AW5: N/A | AX5: N/A | AY5: N/A | AZ5: N/A | BA5: N/A | BB5: N/A | BC5: N/A | BD5: N/A | BE5: N/A | BF5: N/A | BG5: N/A | BH5: N/A | BI5: N/A | BJ5: N/A | BK5: N/A | BL5: N/A | BM5: N/A | BN5: N/A | BO5: No | BP5: N/A | BQ5: N/A | BR5: contrôle qualité
A6: AMP-13-011D | B6: banc_test | C6: UPDATE | D6: MAJ 10/12/2025 | E6: desktop | F6: Attendre autorisation Arnaud | G6: Dell Inc. - Precision T1650 | H6: Intel(R) Core(TM) i7-3770 CPU @ 3.40GHz | I6: Off | J6: 185.149.219.108 | K6: 23.4.4.223 | L6: 16M8WX1 | M6: Jun 06, 2023 01:29:14 PM | N6: Windows 10 Professionnel,19045 | O6: 64 bit | P6: 8 GB | S6: Historique | T6: 1 | U6: 4 | V6: Offline | W6: Connected | X6: Up to date | Y6: N/A | Z6: 192.168.17.2 | AA6: No | AB6: db6c5259662c4f16ab356c5f233f1dfd | AC6: 1.70146e+18 | AD6: N/A | AE6: N/A | AF6: Not disabled | AG6: N/A | AH6: May 19, 2025 07:50:55 AM | AI6: MSI | AJ6: No | AK6: No | AL6: disabled | AM6: N/A | AN6: N/A | AO6: N/A | AP6: N/A | AQ6: N/A | AR6: N/A | AS6: N/A | AT6: N/A | AU6: N/A | AV6: N/A | AW6: N/A | AX6: N/A | AY6: N/A | AZ6: N/A | BA6: N/A | BB6: N/A | BC6: N/A | BD6: N/A | BE6: N/A | BF6: N/A | BG6: N/A | BH6: N/A | BI6: N/A | BJ6: N/A | BK6: N/A | BL6: N/A | BM6: N/A | BN6: N/A | BO6: No | BP6: N/A | BQ6: N/A | BR6: EOL / LABO
A7: AMP-13-021D | B7: gberva | C7: UPDATE | D7: MAJ le 08/12/2025 | E7: desktop | F7: voir avec Djamel | G7: Dell Inc. - Precision T1700 | H7: Intel(R) Core(TM) i7-4770 CPU @ 3.40GHz | I7: Off | J7: 185.149.219.108 | K7: 23.4.4.223 | L7: 3C9GGZ1 | M7: Jun 07, 2023 03:09:29 PM | N7: Windows 10 Professionnel,19045 | O7: 64 bit | P7: 16 GB | S7: historique | T7: 1 | U7: 4 | V7: Online | W7: Connected | X7: Up to date | Y7: N/A | Z7: 192.168.17.152 | AA7: No | AB7: df06255281b94da1984102f67dc6c7dd | AC7: 1.70223e+18 | AD7: N/A | AE7: N/A | AF7: Not disabled | AG7: N/A | AH7: May 27, 2025 09:11:01 AM | AI7: MSI | AJ7: No | AK7: No | AL7: disabled | AM7: N/A | AN7: N/A | AO7: N/A | AP7: N/A | AQ7: N/A | AR7: N/A | AS7: N/A | AT7: N/A | AU7: N/A | AV7: N/A | AW7: N/A | AX7: N/A | AY7: N/A | AZ7: N/A | BA7: N/A | BB7: N/A | BC7: N/A | BD7: N/A | BE7: N/A | BF7: N/A | BG7: N/A | BH7: N/A | BI7: N/A | BJ7: N/A | BK7: N/A | BL7: N/A | BM7: N/A | BN7: N/A | BO7: No | BP7: N/A | BQ7: N/A | BR7: contrôle qualité
A8: AMP-13-023D | B8: sremil | C8: A CHANGER | D8: Changé le 11/12/2025 | E8: desktop | G8: Dell Inc. - OptiPlex 3010 | H8: Intel(R) Core(TM) i3-3220 CPU @ 3.30GHz | I8: Off | J8: 185.149.219.108 | K8: 23.4.4.223 | L8: 69TD3Y1 | M8: Jun 08, 2023 08:34:42 AM | N8: Windows 10 Professionnel,19045 | O8: 64 bit | P8: 4 GB | S8: Historique | T8: 1 | U8: 2 | V8: Online | W8: Connected | X8: Up to date | Y8: N/A | Z8: 192.168.16.100 | AA8: No | AB8: 7ad66fe5cc4540c081270684da53f2b4 | AC8: 1.70276e+18 | AD8: N/A | AE8: N/A | AF8: Not disabled | AG8: N/A | AH8: May 15, 2025 06:46:32 AM | AI8: MSI | AJ8: No | AK8: No | AL8: disabled | AM8: N/A | AN8: N/A | AO8: N/A | AP8: N/A | AQ8: N/A | AR8: N/A | AS8: N/A | AT8: N/A | AU8: N/A | AV8: N/A | AW8: N/A | AX8: N/A | AY8: N/A | AZ8: N/A | BA8: N/A | BB8: N/A | BC8: N/A | BD8: N/A | BE8: N/A | BF8: N/A | BG8: N/A | BH8: N/A | BI8: N/A | BJ8: N/A | BK8: N/A | BL8: N/A | BM8: N/A | BN8: N/A | BO8: No | BP8: N/A | BQ8: N/A | BR8: Compta
A9: AMP-14-005D | B9: abaillot | C9: UPDATE | D9: maj 29/10/2025 | E9: desktop | G9: Dell Inc. - OptiPlex 3020 | H9: Intel(R) Core(TM) i3-4130 CPU @ 3.40GHz | I9: Off | J9: 185.149.219.108 | K9: 23.4.4.223 | L9: 3ZTQPZ1 | M9: Jun 13, 2023 09:27:56 AM | N9: Windows 10 Professionnel,19045 | O9: 64 bit | P9: 4 GB | Q9: 4>8 | S9: historique | T9: 1 | U9: 2 | V9: Offline | W9: Connected | X9: Up to date | Y9: Completed( Apr 05, 2024 06:41:52 AM ) | Z9: 172.17.10.157 | AA9: No | AB9: d461ffe4013748d698dd1cc843cd66d7 | AC9: 1.70641e+18 | AD9: N/A | AE9: N/A | AF9: Not disabled | AG9: N/A | AH9: May 23, 2025 02:50:02 PM | AI9: MSI | AJ9: No | AK9: No | AL9: disabled | AM9: N/A | AN9: N/A | AO9: N/A | AP9: N/A | AQ9: N/A | AR9: N/A | AS9: N/A | AT9: N/A | AU9: N/A | AV9: N/A | AW9: N/A | AX9: N/A | AY9: N/A | AZ9: N/A | BA9: N/A | BB9: N/A | BC9: N/A | BD9: N/A | BE9: N/A | BF9: N/A | BG9: N/A | BH9: N/A | BI9: N/A | BJ9: N/A | BK9: N/A | BL9: N/A | BM9: N/A | BN9: N/A | BO9: No | BP9: N/A | BQ9: N/A | BR9: compta
A10: AMP-14-008D | B10: jmortier | C10: UPDATE | D10: MAJ 12/11/25 | E10: desktop | F10: Voir avec Djamel | G10: Dell Inc. - Precision T1700 | H10: Intel(R) Core(TM) i7-4770 CPU @ 3.40GHz | I10: Off | J10: 185.149.219.108 | K10: 23.4.4.223 | L10: BJXBV02 | M10: May 24, 2023 07:53:22 PM | N10: Windows 10 Professionnel,19045 | O10: 64 bit | P10: 16 GB | S10: PROD | T10: 1 | U10: 4 | V10: Online | W10: Connected | X10: Up to date | Y10: N/A | Z10: 192.168.17.17 | AA10: No | AB10: 1db44efd38f64505bee6cf99508f9daa | AC10: 1.69223e+18 | AD10: N/A | AE10: N/A | AF10: Not disabled | AG10: N/A | AH10: May 19, 2025 07:09:39 AM | AI10: MSI | AJ10: No | AK10: No | AL10: disabled | AM10: N/A | AN10: N/A | AO10: N/A | AP10: N/A | AQ10: N/A | AR10: N/A | AS10: N/A | AT10: N/A | AU10: N/A | AV10: N/A | AW10: N/A | AX10: N/A | AY10: N/A | AZ10: N/A | BA10: N/A | BB10: N/A | BC10: N/A | BD10: N/A | BE10: N/A | BF10: N/A | BG10: N/A | BH10: N/A | BI10: N/A | BJ10: N/A | BK10: N/A | BL10: N/A | BM10: N/A | BN10: N/A | BO10: No | BP10: N/A | BQ10: N/A | BR10: contrôle qualité (métrologie)
A11: AMP-14-010L | B11: qlaulagnet | C11: UPDATE | D11: MAJ 25/11/2025 | E11: laptop | F11: A faire le 25/11 MATIN | G11: Dell Inc. - Precision M4800 | H11: Intel(R) Core(TM) i7-4800MQ CPU @ 2.70GHz | I11: On | J11: 185.149.219.108 | K11: 23.4.4.223 | L11: 7MHLYZ1 | M11: Jun 07, 2023 07:15:30 AM | N11: Windows 10 Professionnel,19045 | O11: 64 bit | P11: 8 GB | S11: PROD | T11: 1 | U11: 4 | V11: Offline | W11: Connected | X11: Up to date | Y11: N/A | Z11: 192.168.17.149 | AA11: No | AB11: 6ce2b51a1648454c944b7045a6714778 | AC11: 1.70199e+18 | AD11: N/A | AE11: N/A | AF11: Not disabled | AG11: N/A | AH11: May 21, 2025 07:46:08 AM | AI11: MSI | AJ11: No | AK11: No | AL11: disabled | AM11: N/A | AN11: N/A | AO11: N/A | AP11: N/A | AQ11: N/A | AR11: N/A | AS11: N/A | AT11: N/A | AU11: N/A | AV11: N/A | AW11: N/A | AX11: N/A | AY11: N/A | AZ11: N/A | BA11: N/A | BB11: N/A | BC11: N/A | BD11: N/A | BE11: N/A | BF11: N/A | BG11: N/A | BH11: N/A | BI11: N/A | BJ11: N/A | BK11: N/A | BL11: N/A | BM11: N/A | BN11: N/A | BO11: No | BP11: N/A | BQ11: N/A | BR11: logistique
A12: AMP-14-012D | B12: rreverchon | C12: UPDATE | D12: maj 30/10/2025 | E12: desktop | G12: Dell Inc. - OptiPlex 3020 | H12: Intel(R) Core(TM) i3-4130 CPU @ 3.40GHz | I12: Off | J12: 185.149.219.108 | K12: 23.4.4.223 | L12: BPSP212 | M12: Jun 08, 2023 08:37:24 AM | N12: Windows 10 Pro,19045 | O12: 64 bit | P12: 4 GB | Q12: 4>8 | S12: historique | T12: 1 | U12: 2 | V12: Offline | W12: Connected | X12: Up to date | Y12: N/A | Z12: 192.168.17.140 | AA12: No | AB12: 392785bfabc041d2a585db3881d15109 | AC12: 1.70276e+18 | AD12: N/A | AE12: N/A | AF12: Not disabled | AG12: N/A | AH12: May 20, 2025 06:08:09 AM | AI12: MSI | AJ12: No | AK12: No | AL12: disabled | AM12: N/A | AN12: N/A | AO12: N/A | AP12: N/A | AQ12: N/A | AR12: N/A | AS12: N/A | AT12: N/A | AU12: N/A | AV12: N/A | AW12: N/A | AX12: N/A | AY12: N/A | AZ12: N/A | BA12: N/A | BB12: N/A | BC12: N/A | BD12: N/A | BE12: N/A | BF12: N/A | BG12: N/A | BH12: N/A | BI12: N/A | BJ12: N/A | BK12: N/A | BL12: N/A | BM12: N/A | BN12: N/A | BO12: No | BP12: N/A | BQ12: N/A | BR12: réception
A13: AMP-14-018D | B13: Administrateur | C13: UPDATE | D13: MAJ 13/11/2025 | E13: desktop | F13: Voir avec Djamel | G13: Dell Inc. - Precision T1700 | H13: Intel(R) Core(TM) i7-4770 CPU @ 3.40GHz | I13: Off | J13: 185.149.219.108 | K13: 23.4.4.223 | L13: 3LDN212 | M13: May 31, 2023 06:23:39 PM | N13: Windows 10 Professionnel,19045 | O13: 64 bit | P13: 16 GB | S13: PROD | T13: 1 | U13: 4 | V13: Online | W13: Connected | X13: Up to date | Y13: N/A | Z13: 192.168.17.42 | AA13: No | AB13: 87d6295c77cd4caab856b03f03cfa9bc | AC13: 1.69726e+18 | AD13: N/A | AE13: N/A | AF13: Not disabled | AG13: N/A | AH13: May 27, 2025 12:21:04 PM | AI13: MSI | AJ13: No | AK13: No | AL13: disabled | AM13: N/A | AN13: N/A | AO13: N/A | AP13: N/A | AQ13: N/A | AR13: N/A | AS13: N/A | AT13: N/A | AU13: N/A | AV13: N/A | AW13: N/A | AX13: N/A | AY13: N/A | AZ13: N/A | BA13: N/A | BB13: N/A | BC13: N/A | BD13: N/A | BE13: N/A | BF13: N/A | BG13: N/A | BH13: N/A | BI13: N/A | BJ13: N/A | BK13: N/A | BL13: N/A | BM13: N/A | BN13: N/A | BO13: No | BP13: N/A | BQ13: N/A | BR13: contrôle qualité (métrologie)
A14: AMP-14-028D | B14: sbarthelemy | C14: A CHANGER | D14: changé 25/11/2025 | E14: desktop | G14: Dell Inc. - OptiPlex 3020 | H14: Intel(R) Core(TM) i3-4130 CPU @ 3.40GHz | I14: Off | J14: 185.149.219.108 | K14: 23.4.4.223 | L14: 3QSP212 | M14: Jun 08, 2023 08:40:10 AM | N14: Windows 10 Pro,19045 | O14: 64 bit | P14: 4 GB | S14: Historique | T14: 1 | U14: 2 | V14: Online | W14: Connected | X14: Up to date | Y14: N/A | Z14: 192.168.16.26 | AA14: No | AB14: c58d9f19daec4a9aa6ce216a8f8e822f | AC14: 1.70276e+18 | AD14: N/A | AE14: N/A | AF14: Not disabled | AG14: N/A | AH14: May 15, 2025 06:03:50 AM | AI14: MSI | AJ14: No | AK14: No | AL14: disabled | AM14: N/A | AN14: N/A | AO14: N/A | AP14: N/A | AQ14: N/A | AR14: N/A | AS14: N/A | AT14: N/A | AU14: N/A | AV14: N/A | AW14: N/A | AX14: N/A | AY14: N/A | AZ14: N/A | BA14: N/A | BB14: N/A | BC14: N/A | BD14: N/A | BE14: N/A | BF14: N/A | BG14: N/A | BH14: N/A | BI14: N/A | BJ14: N/A | BK14: N/A | BL14: N/A | BM14: N/A | BN14: N/A | BO14: No | BP14: N/A | BQ14: N/A | BR14: achats
A15: AMP-14-058D | B15: cboutaud | C15: UPDATE | D15: Dylan s'en occupera | E15: desktop | F15: trouver un créneau avec Adrien | G15: Dell Inc. - Precision T1700 | H15: Intel(R) Core(TM) i7-4790 CPU @ 3.60GHz | I15: Off | J15: 185.149.219.108 | K15: 23.4.4.223 | L15: 3ZPMJ32 | M15: Jun 05, 2023 05:32:14 PM | N15: Windows 10 Professionnel,19045 | O15: 64 bit | P15: 16 GB | S15: historique | T15: 1 | U15: 4 | V15: Online | W15: Connected | X15: Up to date | Y15: N/A | Z15: 192.168.16.106 | AA15: No | AB15: 51b48313da64452e953a9d048d9e9e65 | AC15: 1.70085e+18 | AD15: N/A | AE15: N/A | AF15: Not disabled | AG15: N/A | AH15: May 19, 2025 06:36:05 AM | AI15: MSI | AJ15: No | AK15: No | AL15: disabled | AM15: N/A | AN15: N/A | AO15: N/A | AP15: N/A | AQ15: N/A | AR15: N/A | AS15: N/A | AT15: N/A | AU15: N/A | AV15: N/A | AW15: N/A | AX15: N/A | AY15: N/A | AZ15: N/A | BA15: N/A | BB15: N/A | BC15: N/A | BD15: N/A | BE15: N/A | BF15: N/A | BG15: N/A | BH15: N/A | BI15: N/A | BJ15: N/A | BK15: N/A | BL15: N/A | BM15: N/A | BN15: N/A | BO15: No | BP15: N/A | BQ15: N/A | BR15: image
A16: AMP-15-001D | B16: mmoreira | C16: UPDATE | D16: maj 27/10/2025 | E16: desktop | G16: Dell Inc. - OptiPlex 3020 | H16: Intel(R) Core(TM) i3-4150 CPU @ 3.50GHz | I16: Off | J16: 185.149.219.108 | K16: 23.4.4.223 | L16: BPD0J42 | M16: Jun 08, 2023 08:48:00 AM | N16: Windows 10 Professionnel,19045 | O16: 64 bit | P16: 4 GB | Q16: 4>8 | R16: mperrod, mmoreira, lmarion, vwrobleski,stracol, compte inconnu | S16: PROD | T16: 1 | U16: 2 | V16: Offline | W16: Connected | X16: Up to date | Y16: N/A | Z16: 192.168.16.101 | AA16: No | AB16: 0f036b71836243a48badfc6a2a2f2b5e | AC16: 1.70276e+18 | AD16: N/A | AE16: N/A | AF16: Not disabled | AG16: N/A | AH16: May 21, 2025 06:43:13 AM | AI16: MSI | AJ16: No | AK16: No | AL16: disabled | AM16: N/A | AN16: N/A | AO16: N/A | AP16: N/A | AQ16: N/A | AR16: N/A | AS16: N/A | AT16: N/A | AU16: N/A | AV16: N/A | AW16: N/A | AX16: N/A | AY16: N/A | AZ16: N/A | BA16: N/A | BB16: N/A | BC16: N/A | BD16: N/A | BE16: N/A | BF16: N/A | BG16: N/A | BH16: N/A | BI16: N/A | BJ16: N/A | BK16: N/A | BL16: N/A | BM16: N/A | BN16: N/A | BO16: No | BP16: N/A | BQ16: N/A | BR16: contrôle qualité (métrologie)
A17: AMP-15-003D | B17: llarue | C17: UPDATE | D17: maj 29/10/2025 | E17: desktop | G17: Dell Inc. - OptiPlex 3020 | H17: Intel(R) Core(TM) i3-4150 CPU @ 3.50GHz | I17: Off | J17: 185.149.219.108 | K17: 23.4.4.223 | L17: DCF0J42 | M17: Jun 08, 2023 08:49:15 AM | N17: Windows 10 Pro,19045 | O17: 64 bit | P17: 4 GB | Q17: 4>8 | S17: historique | T17: 1 | U17: 2 | V17: Offline | W17: Connected | X17: Up to date | Y17: N/A | Z17: 192.168.16.113 | AA17: No | AB17: 9269f00d0ea34357b2dc3addc4f0ff74 | AC17: 1.70276e+18 | AD17: N/A | AE17: N/A | AF17: Not disabled | AG17: N/A | AH17: May 21, 2025 06:22:03 AM | AI17: MSI | AJ17: No | AK17: No | AL17: disabled | AM17: N/A | AN17: N/A | AO17: N/A | AP17: N/A | AQ17: N/A | AR17: N/A | AS17: N/A | AT17: N/A | AU17: N/A | AV17: N/A | AW17: N/A | AX17: N/A | AY17: N/A | AZ17: N/A | BA17: N/A | BB17: N/A | BC17: N/A | BD17: N/A | BE17: N/A | BF17: N/A | BG17: N/A | BH17: N/A | BI17: N/A | BJ17: N/A | BK17: N/A | BL17: N/A | BM17: N/A | BN17: N/A | BO17: No | BP17: N/A | BQ17: N/A | BR17: compta
A18: AMP-15-006D | B18: jllaquet | C18: UPDATE | D18: maj 31/10/2025 | E18: desktop | G18: Dell Inc. - OptiPlex 3020 | H18: Intel(R) Core(TM) i3-4150 CPU @ 3.50GHz | I18: Off | J18: 185.149.219.108 | K18: 23.4.4.223 | L18: F0F0J42 | M18: Jun 08, 2023 08:50:19 AM | N18: Windows 10 Professionnel,19045 | O18: 64 bit | P18: 4 GB | Q18: 4>8 | S18: Logistique | T18: 1 | U18: 2 | V18: Online | W18: Connected | X18: Up to date | Y18: N/A | Z18: 192.168.16.233 | AA18: No | AB18: 6174e4cbb1764c96a1685dc00f09f58e | AC18: 1.70277e+18 | AD18: N/A | AE18: N/A | AF18: Not disabled | AG18: N/A | AH18: May 15, 2025 06:30:08 AM | AI18: MSI | AJ18: No | AK18: No | AL18: disabled | AM18: N/A | AN18: N/A | AO18: N/A | AP18: N/A | AQ18: N/A | AR18: N/A | AS18: N/A | AT18: N/A | AU18: N/A | AV18: N/A | AW18: N/A | AX18: N/A | AY18: N/A | AZ18: N/A | BA18: N/A | BB18: N/A | BC18: N/A | BD18: N/A | BE18: N/A | BF18: N/A | BG18: N/A | BH18: N/A | BI18: N/A | BJ18: N/A | BK18: N/A | BL18: N/A | BM18: N/A | BN18: N/A | BO18: No | BP18: N/A | BQ18: N/A | BR18: achats
A19: AMP-15-007D | B19: gleger | C19: UPDATE | D19: maj 31/10/2025 | E19: desktop | G19: Dell Inc. - OptiPlex 3020 | H19: Intel(R) Core(TM) i3-4150 CPU @ 3.50GHz | I19: Off | J19: 185.149.219.108 | K19: 23.4.4.223 | L19: DJD0J42 | M19: Jun 08, 2023 08:50:43 AM | N19: Windows 10 Pro,19045 | O19: 64 bit | P19: 4 GB | Q19: 4>8 | S19: Logistique | T19: 1 | U19: 2 | V19: Online | W19: Connected | X19: Up to date | Y19: N/A | Z19: 192.168.17.85 | AA19: No | AB19: 8ff0b984efb2490e8d48281832ea23ba | AC19: 1.70277e+18 | AD19: N/A | AE19: N/A | AF19: Not disabled | AG19: N/A | AH19: May 14, 2025 07:26:10 AM | AI19: MSI | AJ19: No | AK19: No | AL19: disabled | AM19: N/A | AN19: N/A | AO19: N/A | AP19: N/A | AQ19: N/A | AR19: N/A | AS19: N/A | AT19: N/A | AU19: N/A | AV19: N/A | AW19: N/A | AX19: N/A | AY19: N/A | AZ19: N/A | BA19: N/A | BB19: N/A | BC19: N/A | BD19: N/A | BE19: N/A | BF19: N/A | BG19: N/A | BH19: N/A | BI19: N/A | BJ19: N/A | BK19: N/A | BL19: N/A | BM19: N/A | BN19: N/A | BO19: No | BP19: N/A | BQ19: N/A | BR19: SAV
A20: AMP-15-025L | B20: aughettomonfrin | C20: A CHANGER | D20: changé 23/09/2025 | E20: laptop | G20: Dell Inc. - Latitude E5550 | H20: Intel(R) Core(TM) i5-5300U CPU @ 2.30GHz | I20: On | J20: 185.149.219.108 | K20: 23.4.4.223 | L20: BP9B262 | M20: Jun 12, 2023 07:44:45 AM | N20: Windows 10 Professionnel,19045 | O20: 64 bit | P20: 8 GB | T20: 1 | U20: 2 | V20: Online | W20: Connected | X20: Up to date | Y20: Completed( Jul 05, 2024 07:43:32 AM ) | Z20: 192.168.16.34 | AA20: No | AB20: 6e24571638d24494a276b861368155fb | AC20: 1.70563e+18 | AD20: N/A | AE20: N/A | AF20: Not disabled | AG20: N/A | AH20: May 19, 2025 06:07:18 AM | AI20: MSI | AJ20: No | AK20: No | AL20: disabled | AM20: N/A | AN20: N/A | AO20: N/A | AP20: N/A | AQ20: N/A | AR20: N/A | AS20: N/A | AT20: N/A | AU20: N/A | AV20: N/A | AW20: N/A | AX20: N/A | AY20: N/A | AZ20: N/A | BA20: N/A | BB20: N/A | BC20: N/A | BD20: N/A | BE20: N/A | BF20: N/A | BG20: N/A | BH20: N/A | BI20: N/A | BJ20: N/A | BK20: N/A | BL20: N/A | BM20: N/A | BN20: N/A | BO20: No | BP20: N/A | BQ20: N/A | BS20: NON
A21: AMP-15-027D | C21: UPDATE | D21: maj 29/10/2025 | E21: desktop | L21: 6KG8832 | O21: 64 bit | P21: 4 GB | Q21: 4>8 | S21: historique | BR21: compta
A22: AMP-15-028L | B22: ggiammona | C22: A CHANGER | D22: changé 06/08/2025 | E22: laptop | G22: Dell Inc. - Latitude E5550 | H22: Intel(R) Core(TM) i5-5300U CPU @ 2.30GHz | I22: On | J22: 185.149.219.108 | K22: 23.4.4.223 | L22: 6MZW262 | M22: Jun 08, 2023 09:18:40 AM | N22: Windows 10 Professionnel,19045 | O22: 64 bit | P22: 8 GB | T22: 1 | U22: 2 | V22: Online | W22: Connected | X22: Up to date | Y22: N/A | Z22: 192.168.17.75 | AA22: No | AB22: d344295c7059494ba43ddb402e1f17cc | AC22: 1.70278e+18 | AD22: N/A | AE22: N/A | AF22: Not disabled | AG22: N/A | AH22: May 15, 2025 06:46:01 AM | AI22: MSI | AJ22: No | AK22: No | AL22: disabled | AM22: N/A | AN22: N/A | AO22: N/A | AP22: N/A | AQ22: N/A | AR22: N/A | AS22: N/A | AT22: N/A | AU22: N/A | AV22: N/A | AW22: N/A | AX22: N/A | AY22: N/A | AZ22: N/A | BA22: N/A | BB22: N/A | BC22: N/A | BD22: N/A | BE22: N/A | BF22: N/A | BG22: N/A | BH22: N/A | BI22: N/A | BJ22: N/A | BK22: N/A | BL22: N/A | BM22: N/A | BN22: N/A | BO22: No | BP22: N/A | BQ22: N/A | BS22: NON
A23: AMP-15-033L | B23: educharne | C23: A CHANGER | D23: changé 25/07/2025 | E23: laptop | G23: Dell Inc. - Latitude E5550 | H23: Intel(R) Core(TM) i5-5300U CPU @ 2.30GHz | I23: On | J23: 185.149.219.108 | K23: 23.4.4.223 | L23: 2XSW262 | M23: Jun 08, 2023 02:55:56 PM | N23: Windows 10 Professionnel,19045 | O23: 64 bit | P23: 8 GB | T23: 1 | U23: 2 | V23: Online | W23: Connected | X23: Up to date | Y23: N/A | Z23: 192.168.16.178 | AA23: No | AB23: 21e9c65b4b6e4c5cab123ff78d5bf8ae | AC23: 1.70295e+18 | AD23: N/A | AE23: N/A | AF23: Not disabled | AG23: N/A | AH23: May 15, 2025 06:19:20 AM | AI23: MSI | AJ23: No | AK23: No | AL23: disabled | AM23: N/A | AN23: N/A | AO23: N/A | AP23: N/A | AQ23: N/A | AR23: N/A | AS23: N/A | AT23: N/A | AU23: N/A | AV23: N/A | AW23: N/A | AX23: N/A | AY23: N/A | AZ23: N/A | BA23: N/A | BB23: N/A | BC23: N/A | BD23: N/A | BE23: N/A | BF23: N/A | BG23: N/A | BH23: N/A | BI23: N/A | BJ23: N/A | BK23: N/A | BL23: N/A | BM23: N/A | BN23: N/A | BO23: No | BP23: N/A | BQ23: N/A
A24: AMP-15-038D | B24: mmoreira | C24: UPDATE | D24: maj 23/10/2025 | E24: desktop | G24: Dell Inc. - OptiPlex 3020M | H24: Intel(R) Core(TM) i3-4160T CPU @ 3.10GHz | I24: Off | J24: 185.149.219.108 | K24: 23.4.4.223 | L24: 7B15C92 | M24: Jun 08, 2023 09:33:16 AM | N24: Windows 10 Professionnel,19045 | O24: 64 bit | P24: 4 GB | Q24: 4>8 | S24: Historique | T24: 1 | U24: 2 | V24: Online | W24: Connected | X24: Up to date | Y24: N/A | Z24: 192.168.17.100 | AA24: No | AB24: dcabf2c24946471189dc6a2a00e38a27 | AC24: 1.70279e+18 | AD24: N/A | AE24: N/A | AF24: Not disabled | AG24: N/A | AH24: May 19, 2025 06:17:39 AM | AI24: MSI | AJ24: No | AK24: No | AL24: disabled | AM24: N/A | AN24: N/A | AO24: N/A | AP24: N/A | AQ24: N/A | AR24: N/A | AS24: N/A | AT24: N/A | AU24: N/A | AV24: N/A | AW24: N/A | AX24: N/A | AY24: N/A | AZ24: N/A | BA24: N/A | BB24: N/A | BC24: N/A | BD24: N/A | BE24: N/A | BF24: N/A | BG24: N/A | BH24: N/A | BI24: N/A | BJ24: N/A | BK24: N/A | BL24: N/A | BM24: N/A | BN24: N/A | BO24: No | BP24: N/A | BQ24: N/A | BR24: contrôle qualité
A25: AMP-15-039D | B25: sleclercq | C25: UPDATE | D25: maj 22/10/2025 | E25: desktop | G25: Dell Inc. - OptiPlex 3020M | H25: Intel(R) Core(TM) i3-4160T CPU @ 3.10GHz | I25: Off | J25: 185.149.219.108 | K25: 23.4.4.223 | L25: 7BV3C92 | M25: Jan 08, 2025 07:57:06 AM | N25: Windows 10 Pro,19045 | O25: 64 bit | P25: 4 GB | Q25: 4>8 | S25: Historique | T25: 1 | U25: 2 | V25: Online | W25: Connected | X25: Up to date | Y25: N/A | Z25: 192.168.16.107 | AA25: No | AB25: 087463070c1a406c90dd3d117d42699f | AC25: 2.12311e+18 | AD25: N/A | AE25: N/A | AF25: Not disabled | AG25: N/A | AH25: May 16, 2025 06:14:28 AM | AI25: MSI | AJ25: No | AK25: No | AL25: disabled | AM25: N/A | AN25: N/A | AO25: N/A | AP25: N/A | AQ25: N/A | AR25: N/A | AS25: N/A | AT25: N/A | AU25: N/A | AV25: N/A | AW25: N/A | AX25: N/A | AY25: N/A | AZ25: N/A | BA25: N/A | BB25: N/A | BC25: N/A | BD25: N/A | BE25: N/A | BF25: N/A | BG25: N/A | BH25: N/A | BI25: N/A | BJ25: N/A | BK25: N/A | BL25: N/A | BM25: N/A | BN25: N/A | BO25: No | BP25: N/A | BQ25: N/A | BT25: Viken
A26: AMP-15-045L | B26: cplantier | C26: A CHANGER | D26: changé 28/07/2025 | E26: laptop | G26: Dell Inc. - Latitude E5550 | H26: Intel(R) Core(TM) i5-5300U CPU @ 2.30GHz | I26: On | J26: 185.149.219.108 | K26: 23.4.4.223 | L26: 9GQGF72 | M26: Jun 08, 2023 09:34:41 AM | N26: Windows 10 Pro,19045 | O26: 64 bit | P26: 8 GB | T26: 1 | U26: 2 | V26: Online | W26: Connected | X26: Up to date | Y26: N/A | Z26: 192.168.16.18 | AA26: No | AB26: dc03e04b27b842b29f128a86f476a7aa | AC26: 1.70279e+18 | AD26: N/A | AE26: N/A | AF26: Not disabled | AG26: N/A | AH26: May 15, 2025 05:50:45 AM | AI26: MSI | AJ26: No | AK26: No | AL26: disabled | AM26: N/A | AN26: N/A | AO26: N/A | AP26: N/A | AQ26: N/A | AR26: N/A | AS26: N/A | AT26: N/A | AU26: N/A | AV26: N/A | AW26: N/A | AX26: N/A | AY26: N/A | AZ26: N/A | BA26: N/A | BB26: N/A | BC26: N/A | BD26: N/A | BE26: N/A | BF26: N/A | BG26: N/A | BH26: N/A | BI26: N/A | BJ26: N/A | BK26: N/A | BL26: N/A | BM26: N/A | BN26: N/A | BO26: No | BP26: N/A | BQ26: N/A
A27: AMP-15-046D | B27: jrenault | C27: UPDATE | D27: maj 23/10/2025 | E27: desktop | G27: Dell Inc. - OptiPlex 3020M | H27: Intel(R) Core(TM) i3-4160T CPU @ 3.10GHz | I27: Off | J27: 185.149.219.108 | K27: 23.4.4.223 | L27: 7B78C92 | M27: Jun 08, 2023 09:36:06 AM | N27: Windows 10 Pro,19045 | O27: 64 bit | P27: 4 GB | Q27: 4>8 | S27: Historique | T27: 1 | U27: 2 | V27: Online | W27: Connected | X27: Up to date | Y27: N/A | Z27: 192.168.17.60 | AA27: No | AB27: 15f6d7ed51f14a999022932b56f7b5a6 | AC27: 1.70279e+18 | AD27: N/A | AE27: N/A | AF27: Not disabled | AG27: N/A | AH27: May 19, 2025 03:08:55 PM | AI27: MSI | AJ27: No | AK27: No | AL27: disabled | AM27: N/A | AN27: N/A | AO27: N/A | AP27: N/A | AQ27: N/A | AR27: N/A | AS27: N/A | AT27: N/A | AU27: N/A | AV27: N/A | AW27: N/A | AX27: N/A | AY27: N/A | AZ27: N/A | BA27: N/A | BB27: N/A | BC27: N/A | BD27: N/A | BE27: N/A | BF27: N/A | BG27: N/A | BH27: N/A | BI27: N/A | BJ27: N/A | BK27: N/A | BL27: N/A | BM27: N/A | BN27: N/A | BO27: No | BP27: N/A | BQ27: N/A | BR27: Réception
A28: AMP-16-001D | B28: gberva | C28: UPDATE | D28: MAJ le 08/12/2025 | E28: desktop | F28: voir avec Djamel | G28: Dell Inc. - Precision Tower 5810 | H28: Intel(R) Xeon(R) CPU E5-1607 v3 @ 3.10GHz | I28: Off | J28: 185.149.219.108 | K28: 23.4.4.223 | L28: 6JSCWC2 | M28: Jun 07, 2023 03:29:18 PM | N28: Windows 10 Professionnel,19045 | O28: 64 bit | P28: 8 GB | S28: historique | T28: 1 | U28: 4 | V28: Online | W28: Connected | X28: Up to date | Y28: N/A | Z28: 192.168.17.109 | AA28: No | AB28: 5951968328834077af520741352111ee | AC28: 1.70224e+18 | AD28: N/A | AE28: N/A | AF28: Not disabled | AG28: N/A | AH28: May 21, 2025 06:29:14 AM | AI28: MSI | AJ28: No | AK28: No | AL28: disabled | AM28: N/A | AN28: N/A | AO28: N/A | AP28: N/A | AQ28: N/A | AR28: N/A | AS28: N/A | AT28: N/A | AU28: N/A | AV28: N/A | AW28: N/A | AX28: N/A | AY28: N/A | AZ28: N/A | BA28: N/A | BB28: N/A | BC28: N/A | BD28: N/A | BE28: N/A | BF28: N/A | BG28: N/A | BH28: N/A | BI28: N/A | BJ28: N/A | BK28: N/A | BL28: N/A | BM28: N/A | BN28: N/A | BO28: No | BP28: N/A | BQ28: N/A | BR28: contrôle qualité
A29: AMP-16-010D | B29: lvabre | C29: UPDATE | D29: maj 29/10/2025 | E29: desktop | G29: Dell Inc. - OptiPlex 3040 | H29: Intel(R) Core(TM) i3-6100T CPU @ 3.20GHz | I29: Off | J29: 185.149.219.108 | K29: 23.4.4.223 | L29: 6XJ98C2 | M29: Apr 09, 2025 07:41:47 AM | N29: Windows 10 Pro,19045 | O29: 64 bit | P29: 4 GB | Q29: 4>8 | S29: PROD | T29: 1 | U29: 2 | V29: Online | W29: Connected | X29: Up to date | Y29: N/A | Z29: 192.168.16.111 | AA29: No | AB29: 85c3398f8e16469cb4f7ea3d3be4a7b2 | AC29: 2.18906e+18 | AD29: N/A | AE29: N/A | AF29: Not disabled | AG29: N/A | AH29: May 19, 2025 07:10:19 AM | AI29: MSI | AJ29: No | AK29: No | AL29: disabled | AM29: N/A | AN29: N/A | AO29: N/A | AP29: N/A | AQ29: N/A | AR29: N/A | AS29: N/A | AT29: N/A | AU29: N/A | AV29: N/A | AW29: N/A | AX29: N/A | AY29: N/A | AZ29: N/A | BA29: N/A | BB29: N/A | BC29: N/A | BD29: N/A | BE29: N/A | BF29: N/A | BG29: N/A | BH29: N/A | BI29: N/A | BJ29: N/A | BK29: N/A | BL29: N/A | BM29: N/A | BN29: N/A | BO29: No | BP29: N/A | BQ29: N/A | BR29: logistique
A30: AMP-16-012L | B30: nmathieu | C30: A CHANGER | D30: changé 21/10/2025 | E30: laptop | G30: Dell Inc. - Latitude E5550 | H30: Intel(R) Core(TM) i5-5300U CPU @ 2.30GHz | I30: On | J30: 185.149.219.108 | K30: 23.4.4.223 | L30: GDXBJ72 | M30: Jun 12, 2023 09:30:07 AM | N30: Windows 10 Professionnel,19045 | O30: 64 bit | P30: 8 GB | T30: 1 | U30: 2 | V30: Online | W30: Connected | X30: Up to date | Y30: N/A | Z30: 192.168.152.18 | AA30: No | AB30: e3f993ecb7b14d8f9dab5471d0d15149 | AC30: 1.70568e+18 | AD30: N/A | AE30: N/A | AF30: Not disabled | AG30: N/A | AH30: May 15, 2025 05:47:18 AM | AI30: MSI | AJ30: No | AK30: No | AL30: disabled | AM30: N/A | AN30: N/A | AO30: N/A | AP30: N/A | AQ30: N/A | AR30: N/A | AS30: N/A | AT30: N/A | AU30: N/A | AV30: N/A | AW30: N/A | AX30: N/A | AY30: N/A | AZ30: N/A | BA30: N/A | BB30: N/A | BC30: N/A | BD30: N/A | BE30: N/A | BF30: N/A | BG30: N/A | BH30: N/A | BI30: N/A | BJ30: N/A | BK30: N/A | BL30: N/A | BM30: N/A | BN30: N/A | BO30: No | BP30: N/A | BQ30: N/A | BS30: NON
A31: AMP-16-018L | B31: sdecorme | C31: A CHANGER | D31: changé 08/08/2025 | E31: laptop | G31: Dell Inc. - Latitude E5570 | H31: Intel(R) Core(TM) i5-6300U CPU @ 2.40GHz | I31: On | J31: 185.149.219.108 | K31: 23.4.4.223 | L31: H2DFJC2 | M31: Jun 08, 2023 09:37:44 AM | N31: Windows 10 Professionnel,19045 | O31: 64 bit | P31: 8 GB | T31: 1 | U31: 2 | V31: Online | W31: Connected | X31: Up to date | Y31: N/A | Z31: 192.168.17.16 | AA31: No | AB31: afd47a26970a4532b03b416192143f47 | AC31: 1.70279e+18 | AD31: N/A | AE31: N/A | AF31: Not disabled | AG31: N/A | AH31: May 19, 2025 07:45:40 AM | AI31: MSI | AJ31: No | AK31: No | AL31: disabled | AM31: N/A | AN31: N/A | AO31: N/A | AP31: N/A | AQ31: N/A | AR31: N/A | AS31: N/A | AT31: N/A | AU31: N/A | AV31: N/A | AW31: N/A | AX31: N/A | AY31: N/A | AZ31: N/A | BA31: N/A | BB31: N/A | BC31: N/A | BD31: N/A | BE31: N/A | BF31: N/A | BG31: N/A | BH31: N/A | BI31: N/A | BJ31: N/A | BK31: N/A | BL31: N/A | BM31: N/A | BN31: N/A | BO31: No | BP31: N/A | BQ31: N/A | BS31: NON
A32: AMP-16-020D | B32: mperrod | C32: UPDATE | D32: maj 31/10/2025 | E32: desktop | G32: Dell Inc. - OptiPlex 3040 | H32: Intel(R) Core(TM) i3-6100T CPU @ 3.20GHz | I32: Off | J32: 185.149.219.108 | K32: 23.4.4.223 | L32: 6XP28C2 | M32: Jun 08, 2023 09:38:33 AM | N32: Windows 10 Professionnel,19045 | O32: 64 bit | P32: 4 GB | Q32: 4>8 | S32: PROD | T32: 1 | U32: 2 | V32: Online | W32: Connected | X32: Up to date | Y32: N/A | Z32: 192.168.17.96 | AA32: No | AB32: 451390ec8ef24a8aa1296f91a06b3989 | AC32: 1.70279e+18 | AD32: N/A | AE32: N/A | AF32: Not disabled | AG32: N/A | AH32: May 19, 2025 06:47:40 AM | AI32: MSI | AJ32: No | AK32: No | AL32: disabled | AM32: N/A | AN32: N/A | AO32: N/A | AP32: N/A | AQ32: N/A | AR32: N/A | AS32: N/A | AT32: N/A | AU32: N/A | AV32: N/A | AW32: N/A | AX32: N/A | AY32: N/A | AZ32: N/A | BA32: N/A | BB32: N/A | BC32: N/A | BD32: N/A | BE32: N/A | BF32: N/A | BG32: N/A | BH32: N/A | BI32: N/A | BJ32: N/A | BK32: N/A | BL32: N/A | BM32: N/A | BN32: N/A | BO32: No | BP32: N/A | BQ32: N/A | BR32: contrôle qualité(métrologie)
A33: AMP-16-021D | B33: ffraisse | C33: UPDATE | D33: maj 31/10/2025 | E33: desktop | G33: Dell Inc. - OptiPlex 3040 | H33: Intel(R) Core(TM) i3-6100T CPU @ 3.20GHz | I33: Off | J33: 185.149.219.108 | K33: 23.4.4.223 | L33: 2BLTGD2 | M33: Jun 07, 2023 03:32:12 PM | N33: Windows 10 Professionnel,19045 | O33: 64 bit | P33: 4 GB | Q33: 4>8 | S33: Logistique | T33: 1 | U33: 2 | V33: Online | W33: Connected | X33: Up to date | Y33: N/A | Z33: 192.168.17.49 | AA33: No | AB33: 0002021fab514d11abeba3e86efe2e8e | AC33: 1.70224e+18 | AD33: N/A | AE33: N/A | AF33: Not disabled | AG33: N/A | AH33: May 14, 2025 11:34:21 AM | AI33: MSI | AJ33: No | AK33: No | AL33: disabled | AM33: N/A | AN33: N/A | AO33: N/A | AP33: N/A | AQ33: N/A | AR33: N/A | AS33: N/A | AT33: N/A | AU33: N/A | AV33: N/A | AW33: N/A | AX33: N/A | AY33: N/A | AZ33: N/A | BA33: N/A | BB33: N/A | BC33: N/A | BD33: N/A | BE33: N/A | BF33: N/A | BG33: N/A | BH33: N/A | BI33: N/A | BJ33: N/A | BK33: N/A | BL33: N/A | BM33: N/A | BN33: N/A | BO33: No | BP33: N/A | BQ33: N/A | BR33: Prepa
A34: AMP-16-022L | B34: tvignal | C34: A CHANGER | D34: changé 10/09/2025 | E34: laptop | G34: Dell Inc. - Latitude E5570 | H34: Intel(R) Core(TM) i5-6300U CPU @ 2.40GHz | I34: On | J34: 185.149.219.108 | K34: 23.4.4.223 | L34: JV4FJC2 | M34: Jun 08, 2023 09:39:35 AM | N34: Windows 10 Professionnel,19045 | O34: 64 bit | P34: 8 GB | T34: 1 | U34: 2 | V34: Online | W34: Connected | X34: Up to date | Y34: N/A | Z34: 192.168.17.27 | AA34: No | AB34: 16133cc9ff1a4522a56e0402b0f44c34 | AC34: 1.70279e+18 | AD34: N/A | AE34: N/A | AF34: Not disabled | AG34: N/A | AH34: May 14, 2025 07:58:41 AM | AI34: MSI | AJ34: No | AK34: No | AL34: disabled | AM34: N/A | AN34: N/A | AO34: N/A | AP34: N/A | AQ34: N/A | AR34: N/A | AS34: N/A | AT34: N/A | AU34: N/A | AV34: N/A | AW34: N/A | AX34: N/A | AY34: N/A | AZ34: N/A | BA34: N/A | BB34: N/A | BC34: N/A | BD34: N/A | BE34: N/A | BF34: N/A | BG34: N/A | BH34: N/A | BI34: N/A | BJ34: N/A | BK34: N/A | BL34: N/A | BM34: N/A | BN34: N/A | BO34: No | BP34: N/A | BQ34: N/A | BS34: NON
A35: AMP-16-024D | B35: prtEOL | C35: UPDATE | D35: maj 29/10/2025 | E35: desktop | G35: Dell Inc. - OptiPlex 3040 | H35: Intel(R) Core(TM) i3-6100T CPU @ 3.20GHz | I35: Off | J35: 185.149.219.108 | K35: 23.4.4.223 | L35: 2BWWGD2 | M35: Jun 06, 2023 08:25:11 AM | N35: Windows 10 Professionnel,19045 | O35: 64 bit | P35: 8 GB | S35: Historique | T35: 1 | U35: 2 | V35: Online | W35: Connected | X35: Up to date | Y35: N/A | Z35: 192.168.16.124 | AA35: No | AB35: 9474c465c772405f851dc6f1d31331e2 | AC35: 1.7013e+18 | AD35: N/A | AE35: N/A | AF35: Not disabled | AG35: N/A | AH35: May 16, 2025 08:48:11 AM | AI35: MSI | AJ35: No | AK35: No | AL35: disabled | AM35: N/A | AN35: N/A | AO35: N/A | AP35: N/A | AQ35: N/A | AR35: N/A | AS35: N/A | AT35: N/A | AU35: N/A | AV35: N/A | AW35: N/A | AX35: N/A | AY35: N/A | AZ35: N/A | BA35: N/A | BB35: N/A | BC35: N/A | BD35: N/A | BE35: N/A | BF35: N/A | BG35: N/A | BH35: N/A | BI35: N/A | BJ35: N/A | BK35: N/A | BL35: N/A | BM35: N/A | BN35: N/A | BO35: No | BP35: N/A | BQ35: N/A | BR35: Eol
A36: AMP-17-008L | B36: bguy | C36: A CHANGER | D36: changé 09/10/2025 | E36: laptop | G36: Dell Inc. - Latitude E5570 | H36: Intel(R) Core(TM) i5-6300U CPU @ 2.40GHz | I36: On | J36: 185.149.219.108 | K36: 23.4.4.223 | L36: 3VDZQF2 | M36: Jun 08, 2023 09:44:58 AM | N36: Windows 10 Professionnel,19045 | O36: 64 bit | P36: 8 GB | T36: 1 | U36: 2 | V36: Online | W36: Connected | X36: Up to date | Y36: N/A | Z36: 192.168.16.110 | AA36: No | AB36: d7d2658789af45109764382a23afad58 | AC36: 1.70279e+18 | AD36: N/A | AE36: N/A | AF36: Not disabled | AG36: N/A | AH36: May 19, 2025 03:30:19 PM | AI36: MSI | AJ36: No | AK36: No | AL36: disabled | AM36: N/A | AN36: N/A | AO36: N/A | AP36: N/A | AQ36: N/A | AR36: N/A | AS36: N/A | AT36: N/A | AU36: N/A | AV36: N/A | AW36: N/A | AX36: N/A | AY36: N/A | AZ36: N/A | BA36: N/A | BB36: N/A | BC36: N/A | BD36: N/A | BE36: N/A | BF36: N/A | BG36: N/A | BH36: N/A | BI36: N/A | BJ36: N/A | BK36: N/A | BL36: N/A | BM36: N/A | BN36: N/A | BO36: No | BP36: N/A | BQ36: N/A | BS36: NON
A37: AMP-17-010EOL | B37: lbiet | C37: NE PAS TOUCHER | D37: N/A | E37: laptop | G37: iEi - B336 | H37: Intel(R) Core(TM) i5-4300U CPU @ 1.90GHz | I37: Off | J37: 185.149.219.108 | K37: 23.4.4.223 | L37: 10221PA00-2017-0022 | M37: Jun 12, 2023 07:29:40 AM | N37: Windows 10 Professionnel,19045 | O37: 64 bit | P37: 8 GB | S37: historique | T37: 1 | U37: 2 | V37: Online | W37: Connected | X37: Up to date | Y37: N/A | Z37: 192.168.17.154 | AA37: No | AB37: dffe974478ae495db4176033588f3d98 | AC37: 1.70562e+18 | AD37: N/A | AE37: N/A | AF37: Not disabled | AG37: N/A | AH37: May 22, 2025 12:17:49 PM | AI37: MSI | AJ37: No | AK37: No | AL37: disabled | AM37: N/A | AN37: N/A | AO37: N/A | AP37: N/A | AQ37: N/A | AR37: N/A | AS37: N/A | AT37: N/A | AU37: N/A | AV37: N/A | AW37: N/A | AX37: N/A | AY37: N/A | AZ37: N/A | BA37: N/A | BB37: N/A | BC37: N/A | BD37: N/A | BE37: N/A | BF37: N/A | BG37: N/A | BH37: N/A | BI37: N/A | BJ37: N/A | BK37: N/A | BL37: N/A | BM37: N/A | BN37: N/A | BO37: No | BP37: N/A | BQ37: N/A | BR37: Eol
A38: AMP-17-013D | B38: albernard | C38: UPDATE | D38: MAJ 24/11/2025 | E38: desktop | G38: Dell Inc. - OptiPlex 3050 | H38: Intel(R) Core(TM) i3-7100T CPU @ 3.40GHz | I38: Off | J38: 185.149.219.108 | K38: 23.4.4.223 | L38: 7B3GYJ2 | M38: Jun 07, 2023 03:35:03 PM | N38: Windows 10 Professionnel,19045 | O38: 64 bit | P38: 8 GB | S38: Historique | T38: 1 | U38: 2 | V38: Online | W38: Connected | X38: Up to date | Y38: N/A | Z38: 192.168.16.22 | AA38: No | AB38: 68f9a35043a94fd0a4160088fb6cf897 | AC38: 1.70224e+18 | AD38: N/A | AE38: N/A | AF38: Not disabled | AG38: N/A | AH38: May 23, 2025 01:07:21 PM | AI38: MSI | AJ38: No | AK38: No | AL38: disabled | AM38: N/A | AN38: N/A | AO38: N/A | AP38: N/A | AQ38: N/A | AR38: N/A | AS38: N/A | AT38: N/A | AU38: N/A | AV38: N/A | AW38: N/A | AX38: N/A | AY38: N/A | AZ38: N/A | BA38: N/A | BB38: N/A | BC38: N/A | BD38: N/A | BE38: N/A | BF38: N/A | BG38: N/A | BH38: N/A | BI38: N/A | BJ38: N/A | BK38: N/A | BL38: N/A | BM38: N/A | BN38: N/A | BO38: No | BP38: N/A | BQ38: N/A | BR38: EOL / LABO
A39: AMP-17-016D | B39: sginet | C39: UPDATE | D39: MAJ 24/11/2025 | E39: desktop | G39: Dell Inc. - OptiPlex 3050 | H39: Intel(R) Core(TM) i3-7100T CPU @ 3.40GHz | I39: Off | J39: 185.149.219.108 | K39: 23.4.4.223 | L39: 7BH7YJ2 | M39: Jun 07, 2023 03:35:09 PM | N39: Windows 10 Professionnel,19045 | O39: 64 bit | P39: 8 GB | S39: Historique | T39: 1 | U39: 2 | V39: Online | W39: Connected | X39: Up to date | Y39: N/A | Z39: 192.168.17.168 | AA39: No | AB39: 10d2fb0be96c40c492faed3e5caf7128 | AC39: 1.70224e+18 | AD39: N/A | AE39: N/A | AF39: Not disabled | AG39: N/A | AH39: May 27, 2025 10:38:12 AM | AI39: MSI | AJ39: No | AK39: No | AL39: disabled | AM39: N/A | AN39: N/A | AO39: N/A | AP39: N/A | AQ39: N/A | AR39: N/A | AS39: N/A | AT39: N/A | AU39: N/A | AV39: N/A | AW39: N/A | AX39: N/A | AY39: N/A | AZ39: N/A | BA39: N/A | BB39: N/A | BC39: N/A | BD39: N/A | BE39: N/A | BF39: N/A | BG39: N/A | BH39: N/A | BI39: N/A | BJ39: N/A | BK39: N/A | BL39: N/A | BM39: N/A | BN39: N/A | BO39: No | BP39: N/A | BQ39: N/A | BR39: Eol
A40: AMP-17-017EOL | B40: hdarnaud | C40: NE PAS TOUCHER | D40: N/A | E40: laptop | G40: iEi - B336 | H40: Intel(R) Core(TM) i5-4300U CPU @ 1.90GHz | I40: Off | J40: 185.149.219.108 | K40: 23.4.4.223 | L40: 10221PA00-2017-0021 | M40: Jun 08, 2023 09:53:16 AM | N40: Windows 10 Professionnel,19045 | O40: 64 bit | P40: 8 GB | S40: historique | BR40: Eol
...

Sheet W11->25H2
B1: amp-h90m2c4-l | C1: Bseux | D1: Achat | E1: OK
B2: amp-77xbj72-l | C2: mroussin | D2: PROD | E2: OK
B3: amp-7xd0j42-d | C3: magups | D3: LOGI | E3: OK
B4: amp-d1c6y52-l | C4: rsichouc | D4: MAINT | E4: OK
B5: amp-hld0j42-d | C5: adiaw | D5: EXPORT | E5: OK
B6: amp-3kh3h92-d | C6: clarpin | D6: COMPTA | E6: OK
B7: amp-2xrxz84-d | C7: cgounon | D7: UTILE ? | E7: OK
B8: amp-6ysw262-l | C8: msoilihi | D8: CSE | E8: OK
B9: amp-fhxbv02-d | C9: image | D9: IMAGE | E9: OK
B10: amp-3657hr2-l | C10: tmarion | D10: LOGI | E10: OK
B11: amp-grm4c12-d | C11: crichard | D11: COMPTA | E11: OK
B12: amp-8xt6m12-l | C12: mgiroud | D12: MAINT | E12: OK

Sheet Avancement
B2: NB PC en W10 | C2: =C7+C8 -> 74 | D2: Fait | E2: =C2-E7-E8 -> 1 | F2: Reste à faire
B3: LAPTOP à changer | C3: {=SUMPRODUCT((Parc!$C$2:$C$105="a changer")*(Parc!$E$2:$E$105="laptop"))} -> 28 | D3: LAPTOP changé | E3: {=SUMPRODUCT((Parc!$E$2:$E$105="laptop")*(ISNUMBER(SEARCH("changé",Parc!D2:D105))))} -> 28 | F3: =C3-E3 -> 0
B4: LAPTOP à upgrade | C4: {=SUMPRODUCT((Parc!$C$2:$C$105="Update")*(Parc!$E$2:$E$105="laptop"))} -> 6 | D4: LAPTOP upgrade | E4: {=SUMPRODUCT((Parc!$E$2:$E$105="laptop")*(ISNUMBER(SEARCH("maj",Parc!D2:D105))))} -> 6 | F4: =C4-E4 -> 0
B5: DESKTOP à changer | C5: {=SUMPRODUCT((Parc!$C$2:$C$105="a changer")*(Parc!$E$2:$E$105="desktop"))} -> 4 | D5: DESKTOP changé | E5: {=SUMPRODUCT((Parc!$E$2:$E$105="desktop")*(ISNUMBER(SEARCH("changé",Parc!D2:D105))))} -> 4 | F5: =C5-E5 -> 0
B6: DESKTOP à upgrade | C6: {=SUMPRODUCT((Parc!$C$2:$C$105="Update")*(Parc!$E$2:$E$105="desktop"))} -> 36 | D6: DESKTOP upgrade | E6: {=SUMPRODUCT((Parc!$E$2:$E$105="desktop")*(ISNUMBER(SEARCH("maj",Parc!D2:D105))))} -> 35 | F6: =C6-E6 -> 1
B7: PC total à CHANGER | C7: =COUNTIF(Parc!C:C,"a changer") -> 32 | D7: PC changé | E7: {=SUMPRODUCT(--(ISNUMBER(SEARCH("changé",Parc!D:D))))} -> 32 | F7: =C7-E7 -> 0
B8: PC total à UPGRADE | C8: =COUNTIF(Parc!C:C,"UPDATE") -> 42 | D8: PC mis à jour | E8: {=SUMPRODUCT(--(ISNUMBER(SEARCH("MAJ",Parc!D:D))))} -> 41 | F8: =C8-E8 -> 1
B9: PC A NE PAS TOUCHER | C9: =COUNTIF(Parc!C:C,"NE PAS TOUCHER") -> 8
